<?xml version='1.0' encoding='utf-8'?>
<mujoco model="hexapod"><compiler angle="radian" coordinate="local" /><option timestep="0.003" gravity="0 0 -9.81" integrator="implicitfast" iterations="80" ls_iterations="20" /><default><geom type="capsule" size="0.01" density="500" rgba="0.6 0.6 0.6 1" friction="1.0 0.02 0.002" solref="0.004 1" solimp="0.90 0.95 0.001" /><joint damping="2.5" armature="0.01" limited="true" /><position kp="20" kv="9" /></default><worldbody><geom name="floor" type="plane" size="5 5 0.1" rgba="0.2 0.3 0.4 1" /><body name="torso" pos="0.000000 0.000000 0.100000"><freejoint /><geom name="torso_geom" type="cylinder" size="0.080562 0.020000" rgba="0.4 0.4 0.4 1" /><body name="leg0_hip" pos="0.069769 0.040281 0.000000" euler="0.000000 0.000000 0.523599"><joint name="leg0_coxa" type="hinge" axis="0 0 1" range="-1.047198 1.047198" /><geom name="leg0_coxa_geom" fromto="0.000000 0.000000 0.000000 0.034500 0.000000 0.000000" rgba="0.8 0.4 0.4 1" /><body name="leg0_femur_body" pos="0.034500 0.000000 0.000000"><joint name="leg0_femur" type="hinge" axis="0 1 0" range="-1.570796 1.570796" /><geom name="leg0_femur_geom" fromto="0.000000 0.000000 0.000000 0.064000 0.000000 0.000000" rgba="0.4 0.8 0.4 1" /><body name="leg0_tibia_body" pos="0.064000 0.000000 0.000000"><joint name="leg0_tibia" type="hinge" axis="0 1 0" range="-2.443461 0.000000" /><geom name="leg0_tibia_geom" fromto="0.000000 0.000000 0.000000 0.086710 0.000000 0.000000" rgba="0.4 0.4 0.8 1" /><site name="foot_leg0" pos="0.086710 0.000000 0.000000" size="0.01" rgba="0.2 0.9 0.9 1" /></body></body></body><body name="leg1_hip" pos="0.000000 0.080562 0.000000" euler="0.000000 0.000000 1.570796"><joint name="leg1_coxa" type="hinge" axis="0 0 1" range="-1.047198 1.047198" /><geom name="leg1_coxa_geom" fromto="0.000000 0.000000 0.000000 0.034500 0.000000 0.000000" rgba="0.8 0.4 0.4 1" /><body name="leg1_femur_body" pos="0.034500 0.000000 0.000000"><joint name="leg1_femur" type="hinge" axis="0 1 0" range="-1.570796 1.570796" /><geom name="leg1_femur_geom" fromto="0.000000 0.000000 0.000000 0.064000 0.000000 0.000000" rgba="0.4 0.8 0.4 1" /><body name="leg1_tibia_body" pos="0.064000 0.000000 0.000000"><joint name="leg1_tibia" type="hinge" axis="0 1 0" range="-2.443461 0.000000" /><geom name="leg1_tibia_geom" fromto="0.000000 0.000000 0.000000 0.086710 0.000000 0.000000" rgba="0.4 0.4 0.8 1" /><site name="foot_leg1" pos="0.086710 0.000000 0.000000" size="0.01" rgba="0.2 0.9 0.9 1" /></body></body></body><body name="leg2_hip" pos="-0.069769 0.040281 0.000000" euler="0.000000 0.000000 2.617994"><joint name="leg2_coxa" type="hinge" axis="0 0 1" range="-1.047198 1.047198" /><geom name="leg2_coxa_geom" fromto="0.000000 0.000000 0.000000 0.034500 0.000000 0.000000" rgba="0.8 0.4 0.4 1" /><body name="leg2_femur_body" pos="0.034500 0.000000 0.000000"><joint name="leg2_femur" type="hinge" axis="0 1 0" range="-1.570796 1.570796" /><geom name="leg2_femur_geom" fromto="0.000000 0.000000 0.000000 0.064000 0.000000 0.000000" rgba="0.4 0.8 0.4 1" /><body name="leg2_tibia_body" pos="0.064000 0.000000 0.000000"><joint name="leg2_tibia" type="hinge" axis="0 1 0" range="-2.443461 0.000000" /><geom name="leg2_tibia_geom" fromto="0.000000 0.000000 0.000000 0.086710 0.000000 0.000000" rgba="0.4 0.4 0.8 1" /><site name="foot_leg2" pos="0.086710 0.000000 0.000000" size="0.01" rgba="0.2 0.9 0.9 1" /></body></body></body><body name="leg3_hip" pos="-0.069769 -0.040281 0.000000" euler="0.000000 0.000000 3.665191"><joint name="leg3_coxa" type="hinge" axis="0 0 1" range="-1.047198 1.047198" /><geom name="leg3_coxa_geom" fromto="0.000000 0.000000 0.000000 0.034500 0.000000 0.000000" rgba="0.8 0.4 0.4 1" /><body name="leg3_femur_body" pos="0.034500 0.000000 0.000000"><joint name="leg3_femur" type="hinge" axis="0 1 0" range="-1.570796 1.570796" /><geom name="leg3_femur_geom" fromto="0.000000 0.000000 0.000000 0.064000 0.000000 0.000000" rgba="0.4 0.8 0.4 1" /><body name="leg3_tibia_body" pos="0.064000 0.000000 0.000000"><joint name="leg3_tibia" type="hinge" axis="0 1 0" range="-2.443461 0.000000" /><geom name="leg3_tibia_geom" fromto="0.000000 0.000000 0.000000 0.086710 0.000000 0.000000" rgba="0.4 0.4 0.8 1" /><site name="foot_leg3" pos="0.086710 0.000000 0.000000" size="0.01" rgba="0.2 0.9 0.9 1" /></body></body></body><body name="leg4_hip" pos="-0.000000 -0.080562 0.000000" euler="0.000000 0.000000 4.712389"><joint name="leg4_coxa" type="hinge" axis="0 0 1" range="-1.047198 1.047198" /><geom name="leg4_coxa_geom" fromto="0.000000 0.000000 0.000000 0.034500 0.000000 0.000000" rgba="0.8 0.4 0.4 1" /><body name="leg4_femur_body" pos="0.034500 0.000000 0.000000"><joint name="leg4_femur" type="hinge" axis="0 1 0" range="-1.570796 1.570796" /><geom name="leg4_femur_geom" fromto="0.000000 0.000000 0.000000 0.064000 0.000000 0.000000" rgba="0.4 0.8 0.4 1" /><body name="leg4_tibia_body" pos="0.064000 0.000000 0.000000"><joint name="leg4_tibia" type="hinge" axis="0 1 0" range="-2.443461 0.000000" /><geom name="leg4_tibia_geom" fromto="0.000000 0.000000 0.000000 0.086710 0.000000 0.000000" rgba="0.4 0.4 0.8 1" /><site name="foot_leg4" pos="0.086710 0.000000 0.000000" size="0.01" rgba="0.2 0.9 0.9 1" /></body></body></body><body name="leg5_hip" pos="0.069769 -0.040281 0.000000" euler="0.000000 0.000000 5.759587"><joint name="leg5_coxa" type="hinge" axis="0 0 1" range="-1.047198 1.047198" /><geom name="leg5_coxa_geom" fromto="0.000000 0.000000 0.000000 0.034500 0.000000 0.000000" rgba="0.8 0.4 0.4 1" /><body name="leg5_femur_body" pos="0.034500 0.000000 0.000000"><joint name="leg5_femur" type="hinge" axis="0 1 0" range="-1.570796 1.570796" /><geom name="leg5_femur_geom" fromto="0.000000 0.000000 0.000000 0.064000 0.000000 0.000000" rgba="0.4 0.8 0.4 1" /><body name="leg5_tibia_body" pos="0.064000 0.000000 0.000000"><joint name="leg5_tibia" type="hinge" axis="0 1 0" range="-2.443461 0.000000" /><geom name="leg5_tibia_geom" fromto="0.000000 0.000000 0.000000 0.086710 0.000000 0.000000" rgba="0.4 0.4 0.8 1" /><site name="foot_leg5" pos="0.086710 0.000000 0.000000" size="0.01" rgba="0.2 0.9 0.9 1" /></body></body></body></body></worldbody><actuator><position name="act_leg0_coxa" joint="leg0_coxa" kp="20" kv="9" ctrlrange="-1.047198 1.047198" /><position name="act_leg0_femur" joint="leg0_femur" kp="20" kv="9" ctrlrange="-1.570796 1.570796" /><position name="act_leg0_tibia" joint="leg0_tibia" kp="20" kv="9" ctrlrange="-2.443461 0.000000" /><position name="act_leg1_coxa" joint="leg1_coxa" kp="20" kv="9" ctrlrange="-1.047198 1.047198" /><position name="act_leg1_femur" joint="leg1_femur" kp="20" kv="9" ctrlrange="-1.570796 1.570796" /><position name="act_leg1_tibia" joint="leg1_tibia" kp="20" kv="9" ctrlrange="-2.443461 0.000000" /><position name="act_leg2_coxa" joint="leg2_coxa" kp="20" kv="9" ctrlrange="-1.047198 1.047198" /><position name="act_leg2_femur" joint="leg2_femur" kp="20" kv="9" ctrlrange="-1.570796 1.570796" /><position name="act_leg2_tibia" joint="leg2_tibia" kp="20" kv="9" ctrlrange="-2.443461 0.000000" /><position name="act_leg3_coxa" joint="leg3_coxa" kp="20" kv="9" ctrlrange="-1.047198 1.047198" /><position name="act_leg3_femur" joint="leg3_femur" kp="20" kv="9" ctrlrange="-1.570796 1.570796" /><position name="act_leg3_tibia" joint="leg3_tibia" kp="20" kv="9" ctrlrange="-2.443461 0.000000" /><position name="act_leg4_coxa" joint="leg4_coxa" kp="20" kv="9" ctrlrange="-1.047198 1.047198" /><position name="act_leg4_femur" joint="leg4_femur" kp="20" kv="9" ctrlrange="-1.570796 1.570796" /><position name="act_leg4_tibia" joint="leg4_tibia" kp="20" kv="9" ctrlrange="-2.443461 0.000000" /><position name="act_leg5_coxa" joint="leg5_coxa" kp="20" kv="9" ctrlrange="-1.047198 1.047198" /><position name="act_leg5_femur" joint="leg5_femur" kp="20" kv="9" ctrlrange="-1.570796 1.570796" /><position name="act_leg5_tibia" joint="leg5_tibia" kp="20" kv="9" ctrlrange="-2.443461 0.000000" /></actuator><contact><exclude name="leg0_coxa_femur" body1="leg0_hip" body2="leg0_femur_body" /><exclude name="leg0_femur_tibia" body1="leg0_femur_body" body2="leg0_tibia_body" /><exclude name="leg1_coxa_femur" body1="leg1_hip" body2="leg1_femur_body" /><exclude name="leg1_femur_tibia" body1="leg1_femur_body" body2="leg1_tibia_body" /><exclude name="leg2_coxa_femur" body1="leg2_hip" body2="leg2_femur_body" /><exclude name="leg2_femur_tibia" body1="leg2_femur_body" body2="leg2_tibia_body" /><exclude name="leg3_coxa_femur" body1="leg3_hip" body2="leg3_femur_body" /><exclude name="leg3_femur_tibia" body1="leg3_femur_body" body2="leg3_tibia_body" /><exclude name="leg4_coxa_femur" body1="leg4_hip" body2="leg4_femur_body" /><exclude name="leg4_femur_tibia" body1="leg4_femur_body" body2="leg4_tibia_body" /><exclude name="leg5_coxa_femur" body1="leg5_hip" body2="leg5_femur_body" /><exclude name="leg5_femur_tibia" body1="leg5_femur_body" body2="leg5_tibia_body" /></contact></mujoco>